Traceback (most recent call last):
  File "/usr/local/lib/python3.8/dist-packages/sqlalchemy/engine/base.py", line 145, in __init__
    self._dbapi_connection = engine.raw_connection()
  File "/usr/local/lib/python3.8/dist-packages/sqlalchemy/engine/base.py", line 3292, in raw_connection
    return self.pool.connect()
  File "/usr/local/lib/python3.8/dist-packages/sqlalchemy/pool/base.py", line 452, in connect
    return _ConnectionFairy._checkout(self)
  File "/usr/local/lib/python3.8/dist-packages/sqlalchemy/pool/base.py", line 1269, in _checkout
    fairy = _ConnectionRecord.checkout(pool)
  File "/usr/local/lib/python3.8/dist-packages/sqlalchemy/pool/base.py", line 716, in checkout
    rec = pool._do_get()
  File "/usr/local/lib/python3.8/dist-packages/sqlalchemy/pool/impl.py", line 170, in _do_get
    self._dec_overflow()
  File "/usr/local/lib/python3.8/dist-packages/sqlalchemy/util/langhelpers.py", line 146, in __exit__
    raise exc_value.with_traceback(exc_tb)
  File "/usr/local/lib/python3.8/dist-packages/sqlalchemy/pool/impl.py", line 167, in _do_get
    return self._create_connection()
  File "/usr/local/lib/python3.8/dist-packages/sqlalchemy/pool/base.py", line 393, in _create_connection
    return _ConnectionRecord(self)
  File "/usr/local/lib/python3.8/dist-packages/sqlalchemy/pool/base.py", line 678, in __init__
    self.__connect()
  File "/usr/local/lib/python3.8/dist-packages/sqlalchemy/pool/base.py", line 903, in __connect
    pool.logger.debug("Error on connect(): %s", e)
  File "/usr/local/lib/python3.8/dist-packages/sqlalchemy/util/langhelpers.py", line 146, in __exit__
    raise exc_value.with_traceback(exc_tb)
  File "/usr/local/lib/python3.8/dist-packages/sqlalchemy/pool/base.py", line 898, in __connect
    self.dbapi_connection = connection = pool._invoke_creator(self)
  File "/usr/local/lib/python3.8/dist-packages/sqlalchemy/engine/create.py", line 637, in connect
    return dialect.connect(*cargs, **cparams)
  File "/usr/local/lib/python3.8/dist-packages/sqlalchemy/engine/default.py", line 616, in connect
    return self.loaded_dbapi.connect(*cargs, **cparams)
  File "/usr/local/lib/python3.8/dist-packages/MySQLdb/__init__.py", line 121, in Connect
    return Connection(*args, **kwargs)
  File "/usr/local/lib/python3.8/dist-packages/MySQLdb/connections.py", line 193, in __init__
    super().__init__(*args, **kwargs2)
MySQLdb.OperationalError: (1045, "Access denied for user 'hbnb_dev'@'localhost' (using password: YES)")

The above exception was the direct cause of the following exception:

Traceback (most recent call last):
  File "./console.py", line 5, in <module>
    from models.base_model import BaseModel
  File "/home/puga/Documents/Holberton Git/holbertonschool-AirBnB_clone_v2/models/__init__.py", line 12, in <module>
    storage.reload()
  File "/home/puga/Documents/Holberton Git/holbertonschool-AirBnB_clone_v2/models/engine/db_storage.py", line 65, in reload
    Base.metadata.create_all(self.__engine)
  File "/usr/local/lib/python3.8/dist-packages/sqlalchemy/sql/schema.py", line 5828, in create_all
    bind._run_ddl_visitor(
  File "/usr/local/lib/python3.8/dist-packages/sqlalchemy/engine/base.py", line 3242, in _run_ddl_visitor
    with self.begin() as conn:
  File "/usr/lib/python3.8/contextlib.py", line 113, in __enter__
    return next(self.gen)
  File "/usr/local/lib/python3.8/dist-packages/sqlalchemy/engine/base.py", line 3232, in begin
    with self.connect() as conn:
  File "/usr/local/lib/python3.8/dist-packages/sqlalchemy/engine/base.py", line 3268, in connect
    return self._connection_cls(self)
  File "/usr/local/lib/python3.8/dist-packages/sqlalchemy/engine/base.py", line 147, in __init__
    Connection._handle_dbapi_exception_noconnection(
  File "/usr/local/lib/python3.8/dist-packages/sqlalchemy/engine/base.py", line 2430, in _handle_dbapi_exception_noconnection
    raise sqlalchemy_exception.with_traceback(exc_info[2]) from e
  File "/usr/local/lib/python3.8/dist-packages/sqlalchemy/engine/base.py", line 145, in __init__
    self._dbapi_connection = engine.raw_connection()
  File "/usr/local/lib/python3.8/dist-packages/sqlalchemy/engine/base.py", line 3292, in raw_connection
    return self.pool.connect()
  File "/usr/local/lib/python3.8/dist-packages/sqlalchemy/pool/base.py", line 452, in connect
    return _ConnectionFairy._checkout(self)
  File "/usr/local/lib/python3.8/dist-packages/sqlalchemy/pool/base.py", line 1269, in _checkout
    fairy = _ConnectionRecord.checkout(pool)
  File "/usr/local/lib/python3.8/dist-packages/sqlalchemy/pool/base.py", line 716, in checkout
    rec = pool._do_get()
  File "/usr/local/lib/python3.8/dist-packages/sqlalchemy/pool/impl.py", line 170, in _do_get
    self._dec_overflow()
  File "/usr/local/lib/python3.8/dist-packages/sqlalchemy/util/langhelpers.py", line 146, in __exit__
    raise exc_value.with_traceback(exc_tb)
  File "/usr/local/lib/python3.8/dist-packages/sqlalchemy/pool/impl.py", line 167, in _do_get
    return self._create_connection()
  File "/usr/local/lib/python3.8/dist-packages/sqlalchemy/pool/base.py", line 393, in _create_connection
    return _ConnectionRecord(self)
  File "/usr/local/lib/python3.8/dist-packages/sqlalchemy/pool/base.py", line 678, in __init__
    self.__connect()
  File "/usr/local/lib/python3.8/dist-packages/sqlalchemy/pool/base.py", line 903, in __connect
    pool.logger.debug("Error on connect(): %s", e)
  File "/usr/local/lib/python3.8/dist-packages/sqlalchemy/util/langhelpers.py", line 146, in __exit__
    raise exc_value.with_traceback(exc_tb)
  File "/usr/local/lib/python3.8/dist-packages/sqlalchemy/pool/base.py", line 898, in __connect
    self.dbapi_connection = connection = pool._invoke_creator(self)
  File "/usr/local/lib/python3.8/dist-packages/sqlalchemy/engine/create.py", line 637, in connect
    return dialect.connect(*cargs, **cparams)
  File "/usr/local/lib/python3.8/dist-packages/sqlalchemy/engine/default.py", line 616, in connect
    return self.loaded_dbapi.connect(*cargs, **cparams)
  File "/usr/local/lib/python3.8/dist-packages/MySQLdb/__init__.py", line 121, in Connect
    return Connection(*args, **kwargs)
  File "/usr/local/lib/python3.8/dist-packages/MySQLdb/connections.py", line 193, in __init__
    super().__init__(*args, **kwargs2)
sqlalchemy.exc.OperationalError: (MySQLdb.OperationalError) (1045, "Access denied for user 'hbnb_dev'@'localhost' (using password: YES)")
(Background on this error at: https://sqlTraceback (most recent call last):
  File "/usr/local/lib/python3.8/dist-packages/sqlalchemy/engine/base.py", line 145, in __init__
    self._dbapi_connection = engine.raw_connection()
  File "/usr/local/lib/python3.8/dist-packages/sqlalchemy/engine/base.py", line 3292, in raw_connection
    return self.pool.connect()
  File "/usr/local/lib/python3.8/dist-packages/sqlalchemy/pool/base.py", line 452, in connect
    return _ConnectionFairy._checkout(self)
  File "/usr/local/lib/python3.8/dist-packages/sqlalchemy/pool/base.py", line 1269, in _checkout
    fairy = _ConnectionRecord.checkout(pool)
  File "/usr/local/lib/python3.8/dist-packages/sqlalchemy/pool/base.py", line 716, in checkout
    rec = pool._do_get()
  File "/usr/local/lib/python3.8/dist-packages/sqlalchemy/pool/impl.py", line 170, in _do_get
    self._dec_overflow()
  File "/usr/local/lib/python3.8/dist-packages/sqlalchemy/util/langhelpers.py", line 146, in __exit__
    raise exc_value.with_traceback(exc_tb)
  File "/usr/local/lib/python3.8/dist-packages/sqlalchemy/pool/impl.py", line 167, in _do_get
    return self._create_connection()
  File "/usr/local/lib/python3.8/dist-packages/sqlalchemy/pool/base.py", line 393, in _create_connection
    return _ConnectionRecord(self)
  File "/usr/local/lib/python3.8/dist-packages/sqlalchemy/pool/base.py", line 678, in __init__
    self.__connect()
  File "/usr/local/lib/python3.8/dist-packages/sqlalchemy/pool/base.py", line 903, in __connect
    pool.logger.debug("Error on connect(): %s", e)
  File "/usr/local/lib/python3.8/dist-packages/sqlalchemy/util/langhelpers.py", line 146, in __exit__
    raise exc_value.with_traceback(exc_tb)
  File "/usr/local/lib/python3.8/dist-packages/sqlalchemy/pool/base.py", line 898, in __connect
    self.dbapi_connection = connection = pool._invoke_creator(self)
  File "/usr/local/lib/python3.8/dist-packages/sqlalchemy/engine/create.py", line 637, in connect
    return dialect.connect(*cargs, **cparams)
  File "/usr/local/lib/python3.8/dist-packages/sqlalchemy/engine/default.py", line 616, in connect
    return self.loaded_dbapi.connect(*cargs, **cparams)
  File "/usr/local/lib/python3.8/dist-packages/MySQLdb/__init__.py", line 121, in Connect
    return Connection(*args, **kwargs)
  File "/usr/local/lib/python3.8/dist-packages/MySQLdb/connections.py", line 193, in __init__
    super().__init__(*args, **kwargs2)
MySQLdb.OperationalError: (1045, "Access denied for user 'hbnb_dev'@'localhost' (using password: YES)")

The above exception was the direct cause of the following exception:

Traceback (most recent call last):
  File "./console.py", line 5, in <module>
    from models.base_model import BaseModel
  File "/home/puga/Documents/Holberton Git/holbertonschool-AirBnB_clone_v2/models/__init__.py", line 12, in <module>
    storage.reload()
  File "/home/puga/Documents/Holberton Git/holbertonschool-AirBnB_clone_v2/models/engine/db_storage.py", line 65, in reload
    Base.metadata.create_all(self.__engine)
  File "/usr/local/lib/python3.8/dist-packages/sqlalchemy/sql/schema.py", line 5828, in create_all
    bind._run_ddl_visitor(
  File "/usr/local/lib/python3.8/dist-packages/sqlalchemy/engine/base.py", line 3242, in _run_ddl_visitor
    with self.begin() as conn:
  File "/usr/lib/python3.8/contextlib.py", line 113, in __enter__
    return next(self.gen)
  File "/usr/local/lib/python3.8/dist-packages/sqlalchemy/engine/base.py", line 3232, in begin
    with self.connect() as conn:
  File "/usr/local/lib/python3.8/dist-packages/sqlalchemy/engine/base.py", line 3268, in connect
    return self._connection_cls(self)
  File "/usr/local/lib/python3.8/dist-packages/sqlalchemy/engine/base.py", line 147, in __init__
    Connection._handle_dbapi_exception_noconnection(
  File "/usr/local/lib/python3.8/dist-packages/sqlalchemy/engine/base.py", line 2430, in _handle_dbapi_exception_noconnection
    raise sqlalchemy_exception.with_traceback(exc_info[2]) from e
  File "/usr/local/lib/python3.8/dist-packages/sqlalchemy/engine/base.py", line 145, in __init__
    self._dbapi_connection = engine.raw_connection()
  File "/usr/local/lib/python3.8/dist-packages/sqlalchemy/engine/base.py", line 3292, in raw_connection
    return self.pool.connect()
  File "/usr/local/lib/python3.8/dist-packages/sqlalchemy/pool/base.py", line 452, in connect
    return _ConnectionFairy._checkout(self)
  File "/usr/local/lib/python3.8/dist-packages/sqlalchemy/pool/base.py", line 1269, in _checkout
    fairy = _ConnectionRecord.checkout(pool)
  File "/usr/local/lib/python3.8/dist-packages/sqlalchemy/pool/base.py", line 716, in checkout
    rec = pool._do_get()
  File "/usr/local/lib/python3.8/dist-packages/sqlalchemy/pool/impl.py", line 170, in _do_get
    self._dec_overflow()
  File "/usr/local/lib/python3.8/dist-packages/sqlalchemy/util/langhelpers.py", line 146, in __exit__
    raise exc_value.with_traceback(exc_tb)
  File "/usr/local/lib/python3.8/dist-packages/sqlalchemy/pool/impl.py", line 167, in _do_get
    return self._create_connection()
  File "/usr/local/lib/python3.8/dist-packages/sqlalchemy/pool/base.py", line 393, in _create_connection
    return _ConnectionRecord(self)
  File "/usr/local/lib/python3.8/dist-packages/sqlalchemy/pool/base.py", line 678, in __init__
    self.__connect()
  File "/usr/local/lib/python3.8/dist-packages/sqlalchemy/pool/base.py", line 903, in __connect
    pool.logger.debug("Error on connect(): %s", e)
  File "/usr/local/lib/python3.8/dist-packages/sqlalchemy/util/langhelpers.py", line 146, in __exit__
    raise exc_value.with_traceback(exc_tb)
  File "/usr/local/lib/python3.8/dist-packages/sqlalchemy/pool/base.py", line 898, in __connect
    self.dbapi_connection = connection = pool._invoke_creator(self)
  File "/usr/local/lib/python3.8/dist-packages/sqlalchemy/engine/create.py", line 637, in connect
    return dialect.connect(*cargs, **cparams)
  File "/usr/local/lib/python3.8/dist-packages/sqlalchemy/engine/default.py", line 616, in connect
    return self.loaded_dbapi.connect(*cargs, **cparams)
  File "/usr/local/lib/python3.8/dist-packages/MySQLdb/__init__.py", line 121, in Connect
    return Connection(*args, **kwargs)
  File "/usr/local/lib/python3.8/dist-packages/MySQLdb/connections.py", line 193, in __init__
    super().__init__(*args, **kwargs2)
sqlalchemy.exc.OperationalError: (MySQLdb.OperationalError) (1045, "Access denied for user 'hbnb_dev'@'localhost' (using password: YES)")
(Background on this error at: https://sqlalche.me/e/20/e3q8)alche.me/e/20/e3q8)